<?xml version="1.0"?>
<robot xmlns:xacro="http://ros.org/wiki/xacro" name="three_claw_gripper" >
  <xacro:macro name="three_claw_gripper" params="arm_link:='link_6'">

  <!-- Common properties -->
  <xacro:property name="pkg_path" value="package://crackle_description/meshes"/>
  <xacro:property name="mesh_scale" value="1 1 1"/>
  <!-- The lateral_rack_pinion_gripper mesh is authored in millimetres; scale to metres. -->
  <xacro:property name="mm_scale" value="0.001 0.001 0.001"/>
  <xacro:property name="arm_last_link" value="${arm_link}"/>

  <!-- Placement of the gripper mesh within the gripper_base link.
       Tune these in RViz if the body is not oriented as expected. -->
  <xacro:property name="gripper_mesh_xyz" value="0 0 0"/>
  <xacro:property name="gripper_mesh_rpy" value="0 0 0"/>

  <!-- Lateral rack (jaw) travel, in metres, from fully open (0) to fully closed. -->
  <xacro:property name="rack_travel" value="0.03"/>
  <!-- Where the jaws sit relative to the base origin (long axis of the mesh). -->
  <xacro:property name="jaw_z" value="-0.15"/>
  <xacro:property name="jaw_open_y" value="0.05"/>

  <!-- =========================
       Macro: Gripper Base Link
       ========================= -->
  <xacro:macro name="gripper_base_macro" params="link_name base_mesh:='lateral_rack_pinion_gripper.stl'">
    <link name="${link_name}">
      <visual>
        <origin xyz="${gripper_mesh_xyz}" rpy="${gripper_mesh_rpy}"/>
        <geometry>
          <mesh filename="${pkg_path}/${base_mesh}" scale="${mm_scale}"/>
        </geometry>
        <material name="gripper_blue">
          <color rgba="0.0 0.0 0.5 1"/>
        </material>
      </visual>
    </link>

    <!-- ===== Left rack (jaw) ===== -->
    <link name="left_rack">
      <visual>
        <origin xyz="0 0 0" rpy="0 0 0"/>
        <geometry>
          <box size="0.02 0.01 0.04"/>
        </geometry>
        <material name="rack_grey">
          <color rgba="0.3 0.3 0.3 1"/>
        </material>
      </visual>
    </link>

    <!-- ===== Right rack (jaw) ===== -->
    <link name="right_rack">
      <visual>
        <origin xyz="0 0 0" rpy="0 0 0"/>
        <geometry>
          <box size="0.02 0.01 0.04"/>
        </geometry>
        <material name="rack_grey">
          <color rgba="0.3 0.3 0.3 1"/>
        </material>
      </visual>
    </link>

    <!-- Prismatic rack joints. Both racks are driven symmetrically by the two
         pinion servos, so a single (positive) joint value closes both jaws.
         Positive axis direction points inward (toward the centreline). -->
    <joint name="left_rack_joint" type="prismatic">
      <parent link="${link_name}"/>
      <child link="left_rack"/>
      <origin xyz="0 ${jaw_open_y} ${jaw_z}" rpy="0 0 0"/>
      <axis xyz="0 -1 0"/>
      <limit lower="0.0" upper="${rack_travel}" effort="10.0" velocity="0.1"/>
    </joint>

    <joint name="right_rack_joint" type="prismatic">
      <parent link="${link_name}"/>
      <child link="right_rack"/>
      <origin xyz="0 ${-jaw_open_y} ${jaw_z}" rpy="0 0 0"/>
      <axis xyz="0 1 0"/>
      <limit lower="0.0" upper="${rack_travel}" effort="10.0" velocity="0.1"/>
    </joint>

  </xacro:macro>

  <!-- =========================
       Instantiate the Gripper
       ========================= -->

  <!-- 1) Base link -->
  <xacro:gripper_base_macro link_name="gripper_base"/>

  <!-- 2) Fixed joint to arm -->
  <joint name="gripper_base_joint" type="fixed">
    <parent link="${arm_last_link}"/>
    <child link="gripper_base"/>
    <origin xyz="0 0 0.025" rpy="0.0 0 -0.78"/> <!-- 0.78 -->
  </joint>

  <link name="camera_depth_optical_frame">
    <visual>
      <origin xyz="0 0 0" rpy="0 0 0"/>
      <geometry>
        <mesh filename="${pkg_path}/realsense_d435i.stl" scale="${mesh_scale}"/>
      </geometry>
      <material name="blue">
        <color rgba="0.0 0.0 0.5 1"/>
      </material>
    </visual>
    <inertial>
      <origin xyz="0 0 0" rpy="0 0 0"/>
      <mass value="0.1"/>
      <inertia ixx="0.001" ixy="0.0" ixz="0.0"
               iyy="0.001" iyz="0.0"
               izz="0.001"/>
    </inertial>
  </link>

  <joint name="camera_depth_optical_frame_joint" type="fixed">
    <parent link="gripper_base"/>
    <child link="camera_depth_optical_frame"/>
    <origin xyz="-0.08 0 0.03" rpy="0 0 -1.57"/>
  </joint>

  </xacro:macro> 

</robot>
